2019-02-16 06:29:51.649735: I tensorflow/core/platform/cpu_feature_guard.cc:141] Your CPU supports instructions that this TensorFlow binary was not compiled to use: AVX2 FMA
2019-02-16 06:29:52.156331: W tensorflow/core/framework/op_kernel.cc:1273] OP_REQUIRES failed at save_restore_v2_ops.cc:184 : Not found: ./checkpoint/Sony/model.ckpt.data-00000-of-00001; No such file or directory
loaded ./checkpoint/Sony/model.ckpt
Traceback (most recent call last):
  File "test_Sony.py", line 109, in <module>
    saver.restore(sess, ckpt.model_checkpoint_path)
  File "/usr/lib/python2.7/site-packages/tensorflow/python/training/saver.py", line 1562, in restore
    err, "a Variable name or other graph key that is missing")
tensorflow.python.framework.errors_impl.NotFoundError: Restoring from checkpoint failed. This is most likely due to a Variable name or other graph key that is missing from the checkpoint. Please ensure that you have not altered the graph expected based on the checkpoint. Original error:

./checkpoint/Sony/model.ckpt.data-00000-of-00001; No such file or directory
	 [[node save/RestoreV2 (defined at test_Sony.py:104)  = RestoreV2[dtypes=[DT_FLOAT, DT_FLOAT, DT_FLOAT, DT_FLOAT, DT_FLOAT, ..., DT_FLOAT, DT_FLOAT, DT_FLOAT, DT_FLOAT, DT_FLOAT], _device="/job:localhost/replica:0/task:0/device:CPU:0"](_arg_save/Const_0_0, save/RestoreV2/tensor_names, save/RestoreV2/shape_and_slices)]]

Caused by op u'save/RestoreV2', defined at:
  File "test_Sony.py", line 104, in <module>
    saver = tf.train.Saver()
  File "/usr/lib/python2.7/site-packages/tensorflow/python/training/saver.py", line 1102, in __init__
    self.build()
  File "/usr/lib/python2.7/site-packages/tensorflow/python/training/saver.py", line 1114, in build
    self._build(self._filename, build_save=True, build_restore=True)
  File "/usr/lib/python2.7/site-packages/tensorflow/python/training/saver.py", line 1151, in _build
    build_save=build_save, build_restore=build_restore)
  File "/usr/lib/python2.7/site-packages/tensorflow/python/training/saver.py", line 795, in _build_internal
    restore_sequentially, reshape)
  File "/usr/lib/python2.7/site-packages/tensorflow/python/training/saver.py", line 406, in _AddRestoreOps
    restore_sequentially)
  File "/usr/lib/python2.7/site-packages/tensorflow/python/training/saver.py", line 862, in bulk_restore
    return io_ops.restore_v2(filename_tensor, names, slices, dtypes)
  File "/usr/lib/python2.7/site-packages/tensorflow/python/ops/gen_io_ops.py", line 1466, in restore_v2
    shape_and_slices=shape_and_slices, dtypes=dtypes, name=name)
  File "/usr/lib/python2.7/site-packages/tensorflow/python/framework/op_def_library.py", line 787, in _apply_op_helper
    op_def=op_def)
  File "/usr/lib/python2.7/site-packages/tensorflow/python/util/deprecation.py", line 488, in new_func
    return func(*args, **kwargs)
  File "/usr/lib/python2.7/site-packages/tensorflow/python/framework/ops.py", line 3274, in create_op
    op_def=op_def)
  File "/usr/lib/python2.7/site-packages/tensorflow/python/framework/ops.py", line 1770, in __init__
    self._traceback = tf_stack.extract_stack()

NotFoundError (see above for traceback): Restoring from checkpoint failed. This is most likely due to a Variable name or other graph key that is missing from the checkpoint. Please ensure that you have not altered the graph expected based on the checkpoint. Original error:

./checkpoint/Sony/model.ckpt.data-00000-of-00001; No such file or directory
	 [[node save/RestoreV2 (defined at test_Sony.py:104)  = RestoreV2[dtypes=[DT_FLOAT, DT_FLOAT, DT_FLOAT, DT_FLOAT, DT_FLOAT, ..., DT_FLOAT, DT_FLOAT, DT_FLOAT, DT_FLOAT, DT_FLOAT], _device="/job:localhost/replica:0/task:0/device:CPU:0"](_arg_save/Const_0_0, save/RestoreV2/tensor_names, save/RestoreV2/shape_and_slices)]]

